<?xml version='1.0'?>
<sdf version='1.4'>
	<model name="JetBot_simple">
		<static>false</static>

		<link name='chassis'>
			<pose>0.0 0.0 0.043 1.57079632679 0.0 1.57079632679</pose>

			<collision name='collision'>
				<geometry>
					<mesh>
						<scale>0.001 0.001 0.001</scale>
						<uri>model://jetbot/meshes/JetBot-v3-Chassis.dae</uri>
					</mesh>
				</geometry>
				<surface>
					<friction>
						<ode>
							<mu>0.0</mu>
							<mu2>0.0</mu2>
							<slip1>0.0</slip1>
							<slip2>0.0</slip2>
						</ode>
					</friction>
				</surface>
			</collision>
			<inertial>
				<mass>0.2</mass>
				<inertia> <!-- inertias are tricky to compute -->
				<!-- http://gazebosim.org/tutorials?tut=inertia&cat=build_robot -->
				<ixx>0.083</ixx>       <!-- for a box: ixx = 0.083 * mass * (y*y + z*z) -->
				<ixy>0.0</ixy>         <!-- for a box: ixy = 0 -->
				<ixz>0.0</ixz>         <!-- for a box: ixz = 0 -->
				<iyy>0.083</iyy>       <!-- for a box: iyy = 0.083 * mass * (x*x + z*z) -->
				<iyz>0.0</iyz>         <!-- for a box: iyz = 0 -->
				<izz>0.083</izz>       <!-- for a box: izz = 0.083 * mass * (x*x + y*y) -->
				</inertia>
			</inertial>

			<visual name='visual'>
				<geometry>
					<mesh>
						<scale>0.001 0.001 0.001</scale>
						<uri>model://jetbot/meshes/JetBot-v3-Chassis.dae</uri>
					</mesh>
				</geometry>
			</visual>
		</link>

		<link name="left_wheel">
			<pose>0.03 0.05125 0.03 0.0 0.0 1.57079632679</pose>
			<collision name="collision">
				<geometry>
					<mesh>
						<scale>0.001 0.001 0.001</scale>
						<uri>model://jetbot/meshes/JetBot-v3-Wheel.stl</uri>
					</mesh>
				</geometry>
				<surface>
					<friction>
						<ode>
							<mu>0.8</mu>
							<mu2>0.8</mu2>
							<slip1>0.8</slip1>
							<slip2>0.8</slip2>
						</ode>
					</friction>
				</surface>
			</collision>
			<inertial>
				<mass>0.02</mass>
				<inertia> <!-- inertias are tricky to compute -->
				<!-- http://gazebosim.org/tutorials?tut=inertia&cat=build_robot -->
				<ixx>0.000042</ixx>       <!-- for a box: ixx = 0.083 * mass * (y*y + z*z) -->
				<ixy>0.0</ixy>         <!-- for a box: ixy = 0 -->
				<ixz>0.0</ixz>         <!-- for a box: ixz = 0 -->
				<iyy>0.000021</iyy>       <!-- for a box: iyy = 0.083 * mass * (x*x + z*z) -->
				<iyz>0.0</iyz>         <!-- for a box: iyz = 0 -->
				<izz>0.000021</izz>       <!-- for a box: izz = 0.083 * mass * (x*x + y*y) -->
				</inertia>
			</inertial>
			<visual name="visual">
				<geometry>
					<mesh>
						<scale>0.001 0.001 0.001</scale>
						<uri>model://jetbot/meshes/JetBot-v3-Wheel.stl</uri>
					</mesh>
				</geometry>
				<material>
					<ambient>0.1 0.1 0.1 1</ambient>
					<diffuse>0.1 0.1 0.1 1</diffuse>
					<specular>0 0 0 0</specular>
					<emissive>0 0 0 1</emissive>
				</material>
			</visual>
		</link>

		<link name="right_wheel">
			<pose>0.03 -0.0595 0.03 0.0 0.0 1.57079632679</pose>
			<collision name="collision">
				<geometry>
					<mesh>
						<scale>0.001 0.001 0.001</scale>
						<uri>model://jetbot/meshes/JetBot-v3-Wheel.stl</uri>
					</mesh>
				</geometry>
				<surface>
					<friction>
						<ode>
							<mu>0.8</mu>
							<mu2>0.8</mu2>
							<slip1>0.8</slip1>
							<slip2>0.8</slip2>
						</ode>
					</friction>
				</surface>
			</collision>
			<inertial>
				<mass>0.02</mass>
				<inertia> <!-- inertias are tricky to compute -->
				<!-- http://gazebosim.org/tutorials?tut=inertia&cat=build_robot -->
				<ixx>0.000042</ixx>       <!-- for a box: ixx = 0.083 * mass * (y*y + z*z) -->
				<ixy>0.0</ixy>         <!-- for a box: ixy = 0 -->
				<ixz>0.0</ixz>         <!-- for a box: ixz = 0 -->
				<iyy>0.000021</iyy>       <!-- for a box: iyy = 0.083 * mass * (x*x + z*z) -->
				<iyz>0.0</iyz>         <!-- for a box: iyz = 0 -->
				<izz>0.000021</izz>       <!-- for a box: izz = 0.083 * mass * (x*x + y*y) -->
				</inertia>
			</inertial>
			<visual name="visual">
				<geometry>
					<mesh>
						<scale>0.001 0.001 0.001</scale>
						<uri>model://jetbot/meshes/JetBot-v3-Wheel.stl</uri>
					</mesh>
				</geometry>
				<material>
					<ambient>0.1 0.1 0.1 1</ambient>
					<diffuse>0.1 0.1 0.1 1</diffuse>
					<specular>0 0 0 0</specular>
					<emissive>0 0 0 1</emissive>
				</material>
			</visual>
		</link>

		<joint type="revolute" name="left_wheel_hinge">
			<pose>0 0 0 0 0 0</pose>
			<child>left_wheel</child>
			<parent>chassis</parent>
			<axis>
				<xyz>0 1 0</xyz>
			</axis>
		</joint>

		<joint type="revolute" name="right_wheel_hinge">
			<pose>0 0 0 0 0 0</pose>
			<child>right_wheel</child>
			<parent>chassis</parent>
			<axis>
				<xyz>0 1 0</xyz>
			</axis>
		</joint>

<!--
		<plugin name="diff_drive" filename="libdiff_drive_controller.so">
		 	<type>diff_drive_controller/DiffDriveController</type>
			<left_wheel>left_wheel_hinge</left_wheel>
			<right_wheel>right_wheel_hinge</right_wheel>
			<pose_covariance_diagonal>0.001 0.001 1000000.0 1000000.0 1000000.0 1000.0 </pose_covariance_diagonal>
			<twist_covariance_diagonal>0.001 0.001 1000000.0 1000000.0 1000000.0 1000.0 </twist_covariance_diagonal>
		</plugin>

-->		
		    <plugin name="diff_drive" filename="libgazebo_ros_diff_drive.so">
      			<commandTopic>cmd_vel</commandTopic>
     			 <odometryTopic>odom</odometryTopic>
      			<odometryFrame>odom</odometryFrame>
      			<odometrySource>world</odometrySource>
      			<publishOdomTF>true</publishOdomTF>
      			<robotBaseFrame>base_footprint</robotBaseFrame>
      			<publishWheelTF>false</publishWheelTF>
      			<wheelSeparation>1.1</wheelSeparation>
      			<wheelDiameter>0.6</wheelDiameter>
      			<publishTf>true</publishTf>
      			<publishWheelJointState>true</publishWheelJointState>
      			<legacyMode>false</legacyMode>
      			<updateRate>30</updateRate>
      			<leftJoint>left_wheel_hinge</leftJoint>
      			<rightJoint>right_wheel_hinge</rightJoint>
      			<wheelAcceleration>1</wheelAcceleration>
      			<wheelTorque>20</wheelTorque>
      			<rosDebugLevel>na</rosDebugLevel>
    		</plugin>

	</model>
</sdf>

